#VRML_SIM R2023b utf8

EXTERNPROTO "https://raw.githubusercontent.com/cyberbotics/webots/R2023b/projects/objects/backgrounds/protos/TexturedBackground.proto"
EXTERNPROTO "https://raw.githubusercontent.com/cyberbotics/webots/R2023b/projects/objects/backgrounds/protos/TexturedBackgroundLight.proto"
EXTERNPROTO "https://raw.githubusercontent.com/cyberbotics/webots/R2023b/projects/objects/floors/protos/Floor.proto"

WorldInfo {
  basicTimeStep 16
}
Viewpoint {
  orientation 0.23174924038807357 0.047976054032922176 -0.9715917804402121 2.7446048302715065
  position 1.9470974964842158 1.0159025552737988 1.2399625560195275
}
TexturedBackground {
}
TexturedBackgroundLight {
}
Floor {
  size 1 1
}
DEF WALL_1 Solid {
  translation 0 0.5 0.05
  children [
    DEF WALL Shape {
      appearance PBRAppearance {
        baseColor 0 0 1
        roughness 0.5
        metalness 0
      }
      geometry Box {
        size 1 0.025 0.1
      }
    }
  ]
  name "solid(3)"
  boundingObject USE WALL
}
DEF WALL_2 Solid {
  translation 0 -0.5 0.05
  children [
    USE WALL
  ]
  name "solid(4)"
  boundingObject USE WALL
}
DEF WALL_3 Solid {
  translation 0.5 0 0.05
  rotation 0 0 1 -1.5707953071795862
  children [
    USE WALL
  ]
  name "solid(5)"
  boundingObject USE WALL
}
DEF WALL_4 Solid {
  translation -0.5 -1.01961e-06 0.05
  rotation 0 0 1 -1.5707953071795862
  children [
    USE WALL
  ]
  name "solid(6)"
  boundingObject USE WALL
}
Robot {
  translation 3.258088267090538e-07 3.464568359014074e-09 0.03986028952517316
  rotation -0.010966825757621682 0.9999398625581153 2.4339597085805805e-07 8.005441416526173e-06
  children [
    DistanceSensor {
      translation 0.1 0.02 0
      rotation 0 0 1 0.3
      children [
        DEF SENSOR Shape {
          appearance PBRAppearance {
            baseColor 0 0 1
            roughness 1
            metalness 0
          }
          geometry Box {
            size 0.01 0.01 0.01
          }
        }
      ]
      name "ds_left"
      boundingObject USE SENSOR
      physics Physics {
      }
    }
    DEF DS_RIGHT DistanceSensor {
      translation 0.1 -0.02 0
      rotation 0 0 1 -0.3
      children [
        DEF SENSOR Shape {
          appearance PBRAppearance {
            baseColor 0 0 1
            roughness 1
            metalness 0
          }
          geometry Box {
            size 0.01 0.01 0.01
          }
        }
      ]
      name "ds_right"
      boundingObject USE SENSOR
      physics Physics {
      }
    }
    DEF BODY Shape {
      appearance PBRAppearance {
        baseColor 1 0 0
        roughness 1
        metalness 0
      }
      geometry Box {
        size 0.2 0.1 0.05
      }
    }
    HingeJoint {
      jointParameters HingeJointParameters {
        position 1.2439659748670934e-11
        axis 0 1 0
        anchor 0.05 0.06 0
      }
      device [
        RotationalMotor {
          name "wheel1"
        }
      ]
      endPoint DEF WHEEL1 Solid {
        translation 0.05 0.06 0
        rotation 1 3.7320276709988925e-11 -3.732040237147878e-11 1.5707996938995745
        children [
          DEF WHEEL Shape {
            appearance PBRAppearance {
              baseColor 0 1 0
              roughness 1
              metalness 0
            }
            geometry Cylinder {
              height 0.02
              radius 0.04
            }
          }
        ]
        name "wheel1"
        boundingObject USE WHEEL
        physics DEF WHEEL_PH Physics {
        }
      }
    }
    HingeJoint {
      jointParameters HingeJointParameters {
        position 1.2465521220423766e-11
        axis 0 1 0
        anchor -0.05 0.06 0
      }
      device [
        RotationalMotor {
          name "wheel3"
        }
      ]
      endPoint DEF WHEEL2 Solid {
        translation -0.05 0.06 0
        rotation 1 3.740897683971219e-11 -3.740910279986518e-11 1.5707996938995745
        children [
          DEF WHEEL Shape {
            appearance PBRAppearance {
              baseColor 0 1 0
              roughness 1
              metalness 0
            }
            geometry Cylinder {
              height 0.02
              radius 0.04
            }
          }
        ]
        name "wheel2"
        boundingObject USE WHEEL
        physics DEF WHEEL_PH Physics {
        }
      }
    }
    HingeJoint {
      jointParameters HingeJointParameters {
        position 1.2439766026620934e-11
        axis 0 1 0
        anchor 0.05 -0.06 0
      }
      device [
        RotationalMotor {
          name "wheel2"
        }
      ]
      endPoint DEF WHEEL3 Solid {
        translation 0.05 -0.06 0
        rotation 1 3.732075109474124e-11 -3.732087675782839e-11 1.5707996938995745
        children [
          DEF WHEEL Shape {
            appearance PBRAppearance {
              baseColor 0 1 0
              roughness 1
              metalness 0
            }
            geometry Cylinder {
              height 0.02
              radius 0.04
            }
          }
        ]
        name "wheel3"
        boundingObject USE WHEEL
        physics DEF WHEEL_PH Physics {
        }
      }
    }
    HingeJoint {
      jointParameters HingeJointParameters {
        position 1.2465838020978806e-11
        axis 0 1 0
        anchor -0.05 -0.06 0
      }
      device [
        RotationalMotor {
          name "wheel4"
        }
      ]
      endPoint DEF WHEEL4 Solid {
        translation -0.05 -0.06 0
        rotation 1 3.740985445975211e-11 -3.7409980422860136e-11 1.5707996938995745
        children [
          DEF WHEEL Shape {
            appearance PBRAppearance {
              baseColor 0 1 0
              roughness 1
              metalness 0
            }
            geometry Cylinder {
              height 0.02
              radius 0.04
            }
          }
        ]
        name "wheel4"
        boundingObject USE WHEEL
        physics DEF WHEEL_PH Physics {
        }
      }
    }
  ]
  boundingObject USE BODY
  physics Physics {
  }
  controller "four_wheeled_collision_avoidance"
}
